Connect
ERROR:asyncio:unhandled exception during asyncio.run() shutdown
task: <Task finished name='Task-1' coro=<_run_app() done, defined at /home/django/.local/lib/python3.8/site-packages/aiohttp/web.py:289> exception=PermissionError(13, "error while attempting to bind on address ('95.163.234.83', 22): permission denied")>
Traceback (most recent call last):
  File "/home/django/.local/lib/python3.8/site-packages/aiohttp/web.py", line 516, in run_app
    loop.run_until_complete(main_task)
  File "/usr/lib/python3.8/asyncio/base_events.py", line 616, in run_until_complete
    return future.result()
  File "/home/django/.local/lib/python3.8/site-packages/aiohttp/web.py", line 415, in _run_app
    await site.start()
  File "/home/django/.local/lib/python3.8/site-packages/aiohttp/web_runner.py", line 121, in start
    self._server = await loop.create_server(
  File "/usr/lib/python3.8/asyncio/base_events.py", line 1463, in create_server
    raise OSError(err.errno, 'error while attempting '
PermissionError: [Errno 13] error while attempting to bind on address ('95.163.234.83', 22): permission denied
Traceback (most recent call last):
  File "main.py", line 81, in <module>
    main()
  File "main.py", line 77, in main
    web.run_app(app, host=WEB_SERVER_HOST, port=WEB_SERVER_PORT)
  File "/home/django/.local/lib/python3.8/site-packages/aiohttp/web.py", line 516, in run_app
    loop.run_until_complete(main_task)
  File "/usr/lib/python3.8/asyncio/base_events.py", line 616, in run_until_complete
    return future.result()
  File "/home/django/.local/lib/python3.8/site-packages/aiohttp/web.py", line 415, in _run_app
    await site.start()
  File "/home/django/.local/lib/python3.8/site-packages/aiohttp/web_runner.py", line 121, in start
    self._server = await loop.create_server(
  File "/usr/lib/python3.8/asyncio/base_events.py", line 1463, in create_server
    raise OSError(err.errno, 'error while attempting '
PermissionError: [Errno 13] error while attempting to bind on address ('95.163.234.83', 22): permission denied
ERROR:asyncio:Unclosed client session
client_session: <aiohttp.client.ClientSession object at 0x7ffa079d98e0>
ERROR:asyncio:Unclosed connector
connections: ['[(<aiohttp.client_proto.ResponseHandler object at 0x7ffa079a19a0>, 59856.485314635)]']
connector: <aiohttp.connector.TCPConnector object at 0x7ffa079d9700>
Connect
ERROR:asyncio:unhandled exception during asyncio.run() shutdown
task: <Task finished name='Task-1' coro=<_run_app() done, defined at /home/django/.local/lib/python3.8/site-packages/aiohttp/web.py:289> exception=PermissionError(13, "error while attempting to bind on address ('127.0.0.1', 22): permission denied")>
Traceback (most recent call last):
  File "/home/django/.local/lib/python3.8/site-packages/aiohttp/web.py", line 516, in run_app
    loop.run_until_complete(main_task)
  File "/usr/lib/python3.8/asyncio/base_events.py", line 616, in run_until_complete
    return future.result()
  File "/home/django/.local/lib/python3.8/site-packages/aiohttp/web.py", line 415, in _run_app
    await site.start()
  File "/home/django/.local/lib/python3.8/site-packages/aiohttp/web_runner.py", line 121, in start
    self._server = await loop.create_server(
  File "/usr/lib/python3.8/asyncio/base_events.py", line 1463, in create_server
    raise OSError(err.errno, 'error while attempting '
PermissionError: [Errno 13] error while attempting to bind on address ('127.0.0.1', 22): permission denied
Traceback (most recent call last):
  File "main.py", line 81, in <module>
    main()
  File "main.py", line 77, in main
    web.run_app(app, host=WEB_SERVER_HOST, port=WEB_SERVER_PORT)
  File "/home/django/.local/lib/python3.8/site-packages/aiohttp/web.py", line 516, in run_app
    loop.run_until_complete(main_task)
  File "/usr/lib/python3.8/asyncio/base_events.py", line 616, in run_until_complete
    return future.result()
  File "/home/django/.local/lib/python3.8/site-packages/aiohttp/web.py", line 415, in _run_app
    await site.start()
  File "/home/django/.local/lib/python3.8/site-packages/aiohttp/web_runner.py", line 121, in start
    self._server = await loop.create_server(
  File "/usr/lib/python3.8/asyncio/base_events.py", line 1463, in create_server
    raise OSError(err.errno, 'error while attempting '
PermissionError: [Errno 13] error while attempting to bind on address ('127.0.0.1', 22): permission denied
ERROR:asyncio:Unclosed client session
client_session: <aiohttp.client.ClientSession object at 0x7f8ac8b98970>
ERROR:asyncio:Unclosed connector
connections: ['[(<aiohttp.client_proto.ResponseHandler object at 0x7f8ac8be8880>, 60262.942844148)]']
connector: <aiohttp.connector.TCPConnector object at 0x7f8ac8b98790>
Connect
ERROR:asyncio:unhandled exception during asyncio.run() shutdown
task: <Task finished name='Task-1' coro=<_run_app() done, defined at /home/django/.local/lib/python3.8/site-packages/aiohttp/web.py:289> exception=PermissionError(13, "error while attempting to bind on address ('127.0.0.1', 22): permission denied")>
Traceback (most recent call last):
  File "/home/django/.local/lib/python3.8/site-packages/aiohttp/web.py", line 516, in run_app
    loop.run_until_complete(main_task)
  File "/usr/lib/python3.8/asyncio/base_events.py", line 616, in run_until_complete
    return future.result()
  File "/home/django/.local/lib/python3.8/site-packages/aiohttp/web.py", line 415, in _run_app
    await site.start()
  File "/home/django/.local/lib/python3.8/site-packages/aiohttp/web_runner.py", line 121, in start
    self._server = await loop.create_server(
  File "/usr/lib/python3.8/asyncio/base_events.py", line 1463, in create_server
    raise OSError(err.errno, 'error while attempting '
PermissionError: [Errno 13] error while attempting to bind on address ('127.0.0.1', 22): permission denied
Traceback (most recent call last):
  File "main.py", line 81, in <module>
    main()
  File "main.py", line 77, in main
    web.run_app(app, host=WEB_SERVER_HOST, port=WEB_SERVER_PORT)
  File "/home/django/.local/lib/python3.8/site-packages/aiohttp/web.py", line 516, in run_app
    loop.run_until_complete(main_task)
  File "/usr/lib/python3.8/asyncio/base_events.py", line 616, in run_until_complete
    return future.result()
  File "/home/django/.local/lib/python3.8/site-packages/aiohttp/web.py", line 415, in _run_app
    await site.start()
  File "/home/django/.local/lib/python3.8/site-packages/aiohttp/web_runner.py", line 121, in start
    self._server = await loop.create_server(
  File "/usr/lib/python3.8/asyncio/base_events.py", line 1463, in create_server
    raise OSError(err.errno, 'error while attempting '
PermissionError: [Errno 13] error while attempting to bind on address ('127.0.0.1', 22): permission denied
ERROR:asyncio:Unclosed client session
client_session: <aiohttp.client.ClientSession object at 0x7f125ea178e0>
ERROR:asyncio:Unclosed connector
connections: ['[(<aiohttp.client_proto.ResponseHandler object at 0x7f125ea66880>, 60860.321987753)]']
connector: <aiohttp.connector.TCPConnector object at 0x7f125ea17700>
Connect
ERROR:asyncio:unhandled exception during asyncio.run() shutdown
task: <Task finished name='Task-1' coro=<_run_app() done, defined at /home/django/.local/lib/python3.8/site-packages/aiohttp/web.py:289> exception=gaierror(-2, 'Name or service not known')>
Traceback (most recent call last):
  File "/home/django/.local/lib/python3.8/site-packages/aiohttp/web.py", line 516, in run_app
    loop.run_until_complete(main_task)
  File "/usr/lib/python3.8/asyncio/base_events.py", line 616, in run_until_complete
    return future.result()
  File "/home/django/.local/lib/python3.8/site-packages/aiohttp/web.py", line 415, in _run_app
    await site.start()
  File "/home/django/.local/lib/python3.8/site-packages/aiohttp/web_runner.py", line 121, in start
    self._server = await loop.create_server(
  File "/usr/lib/python3.8/asyncio/base_events.py", line 1429, in create_server
    infos = await tasks.gather(*fs, loop=self)
  File "/usr/lib/python3.8/asyncio/base_events.py", line 1369, in _create_server_getaddrinfo
    infos = await self._ensure_resolved((host, port), family=family,
  File "/usr/lib/python3.8/asyncio/base_events.py", line 1365, in _ensure_resolved
    return await loop.getaddrinfo(host, port, family=family, type=type,
  File "/usr/lib/python3.8/asyncio/base_events.py", line 825, in getaddrinfo
    return await self.run_in_executor(
  File "/usr/lib/python3.8/concurrent/futures/thread.py", line 57, in run
    result = self.fn(*self.args, **self.kwargs)
  File "/usr/lib/python3.8/socket.py", line 918, in getaddrinfo
    for res in _socket.getaddrinfo(host, port, family, type, proto, flags):
socket.gaierror: [Errno -2] Name or service not known
Traceback (most recent call last):
  File "main.py", line 81, in <module>
    main()
  File "main.py", line 77, in main
    web.run_app(app, host=WEB_SERVER_HOST, port=WEB_SERVER_PORT)
  File "/home/django/.local/lib/python3.8/site-packages/aiohttp/web.py", line 516, in run_app
    loop.run_until_complete(main_task)
  File "/usr/lib/python3.8/asyncio/base_events.py", line 616, in run_until_complete
    return future.result()
  File "/home/django/.local/lib/python3.8/site-packages/aiohttp/web.py", line 415, in _run_app
    await site.start()
  File "/home/django/.local/lib/python3.8/site-packages/aiohttp/web_runner.py", line 121, in start
    self._server = await loop.create_server(
  File "/usr/lib/python3.8/asyncio/base_events.py", line 1429, in create_server
    infos = await tasks.gather(*fs, loop=self)
  File "/usr/lib/python3.8/asyncio/base_events.py", line 1369, in _create_server_getaddrinfo
    infos = await self._ensure_resolved((host, port), family=family,
  File "/usr/lib/python3.8/asyncio/base_events.py", line 1365, in _ensure_resolved
    return await loop.getaddrinfo(host, port, family=family, type=type,
  File "/usr/lib/python3.8/asyncio/base_events.py", line 825, in getaddrinfo
    return await self.run_in_executor(
  File "/usr/lib/python3.8/concurrent/futures/thread.py", line 57, in run
    result = self.fn(*self.args, **self.kwargs)
  File "/usr/lib/python3.8/socket.py", line 918, in getaddrinfo
    for res in _socket.getaddrinfo(host, port, family, type, proto, flags):
socket.gaierror: [Errno -2] Name or service not known
ERROR:asyncio:Unclosed client session
client_session: <aiohttp.client.ClientSession object at 0x7f7b8e0cc910>
ERROR:asyncio:Unclosed connector
connections: ['[(<aiohttp.client_proto.ResponseHandler object at 0x7f7b8e11a880>, 60962.241267936)]']
connector: <aiohttp.connector.TCPConnector object at 0x7f7b8e0cc730>
Connect
ERROR:asyncio:unhandled exception during asyncio.run() shutdown
task: <Task finished name='Task-1' coro=<_run_app() done, defined at /home/django/.local/lib/python3.8/site-packages/aiohttp/web.py:289> exception=gaierror(-2, 'Name or service not known')>
Traceback (most recent call last):
  File "/home/django/.local/lib/python3.8/site-packages/aiohttp/web.py", line 516, in run_app
    loop.run_until_complete(main_task)
  File "/usr/lib/python3.8/asyncio/base_events.py", line 616, in run_until_complete
    return future.result()
  File "/home/django/.local/lib/python3.8/site-packages/aiohttp/web.py", line 415, in _run_app
    await site.start()
  File "/home/django/.local/lib/python3.8/site-packages/aiohttp/web_runner.py", line 121, in start
    self._server = await loop.create_server(
  File "/usr/lib/python3.8/asyncio/base_events.py", line 1429, in create_server
    infos = await tasks.gather(*fs, loop=self)
  File "/usr/lib/python3.8/asyncio/base_events.py", line 1369, in _create_server_getaddrinfo
    infos = await self._ensure_resolved((host, port), family=family,
  File "/usr/lib/python3.8/asyncio/base_events.py", line 1365, in _ensure_resolved
    return await loop.getaddrinfo(host, port, family=family, type=type,
  File "/usr/lib/python3.8/asyncio/base_events.py", line 825, in getaddrinfo
    return await self.run_in_executor(
  File "/usr/lib/python3.8/concurrent/futures/thread.py", line 57, in run
    result = self.fn(*self.args, **self.kwargs)
  File "/usr/lib/python3.8/socket.py", line 918, in getaddrinfo
    for res in _socket.getaddrinfo(host, port, family, type, proto, flags):
socket.gaierror: [Errno -2] Name or service not known
Traceback (most recent call last):
  File "main.py", line 81, in <module>
    main()
  File "main.py", line 77, in main
    web.run_app(app, host=WEB_SERVER_HOST, port=WEB_SERVER_PORT)
  File "/home/django/.local/lib/python3.8/site-packages/aiohttp/web.py", line 516, in run_app
    loop.run_until_complete(main_task)
  File "/usr/lib/python3.8/asyncio/base_events.py", line 616, in run_until_complete
    return future.result()
  File "/home/django/.local/lib/python3.8/site-packages/aiohttp/web.py", line 415, in _run_app
    await site.start()
  File "/home/django/.local/lib/python3.8/site-packages/aiohttp/web_runner.py", line 121, in start
    self._server = await loop.create_server(
  File "/usr/lib/python3.8/asyncio/base_events.py", line 1429, in create_server
    infos = await tasks.gather(*fs, loop=self)
  File "/usr/lib/python3.8/asyncio/base_events.py", line 1369, in _create_server_getaddrinfo
    infos = await self._ensure_resolved((host, port), family=family,
  File "/usr/lib/python3.8/asyncio/base_events.py", line 1365, in _ensure_resolved
    return await loop.getaddrinfo(host, port, family=family, type=type,
  File "/usr/lib/python3.8/asyncio/base_events.py", line 825, in getaddrinfo
    return await self.run_in_executor(
  File "/usr/lib/python3.8/concurrent/futures/thread.py", line 57, in run
    result = self.fn(*self.args, **self.kwargs)
  File "/usr/lib/python3.8/socket.py", line 918, in getaddrinfo
    for res in _socket.getaddrinfo(host, port, family, type, proto, flags):
socket.gaierror: [Errno -2] Name or service not known
ERROR:asyncio:Unclosed client session
client_session: <aiohttp.client.ClientSession object at 0x7fb30af11970>
ERROR:asyncio:Unclosed connector
connections: ['[(<aiohttp.client_proto.ResponseHandler object at 0x7fb30af5f880>, 61196.258971892)]']
connector: <aiohttp.connector.TCPConnector object at 0x7fb30af11790>
